Workbook

Sheet Cover
B2: CalcGuru
B3: Free CA & Company-Law Templates · calcguru.in
B6: Schedule III Financial Statements — Companies (Division I) — FY 2025-26 template
B7: Balance Sheet, Statement of Profit and Loss, cash flow, notes with ageing schedules, borrowings split, ratios, EPS and regulatory disclosures — as per Schedule III (Division I) to the Companies Act, 2013 (as amended w.e.f. 1 April 2022).
B9: How to use
B10: 1. Fill the Setup sheet (entity, dates, rounding, share capital).
B11: 2. Paste your trial balance in the TB sheet and pick a Map code for every row — the Map Guide sheet explains every code with typical ledgers.
B12: 3. Fill the detail grids: Borrowings, the Fixed Asset Register (FAR), EPS events and the note inputs (ageing, MSMED, contingent liabilities).
B13: 4. Balance Sheet, P&L, notes, ratios and cash flow build themselves. Answer the Additional regulatory information questionnaire on Other Notes.
B14: 5. Open the Checks sheet — every row must say PASS before you print.
B15: 6. Blue cells are your inputs. Everything else is formula-driven.
B17: Legend
... B23: This template is a working tool, not professional advice. Verify every figure and disclosure against the audited books before adoption.

Sheet Setup
B2: Setup
B4: Entity details
B5: Entity name | C5: ABC Private Limited
B6: CIN | C6: U12345TG2020PTC123456
B7: Registered office (one line) | C7: Hyderabad, Telangana
B8: Current financial year label | C8: 2025-26
B9: Balance sheet date | C9: 46112 | D9: dd-mm-yyyy
B10: Previous year label | C10: 2024-25
B11: Previous balance sheet date | C11: 45747
B13: Presentation
B14: Rounding (Sch III mandatory) | C14: Lakhs | D14: Total income < Rs 100 cr: hundreds/thousands/lakhs. Rs 100 cr or more: lakhs/millions/crores.
B15: Amounts are entered in | C15: Rupees (always paste raw rupees)
B16: Company is an SMC (no diluted EPS disclosure) | C16: No
B17: Cash flow statement required | C17: Yes | D17: OPC, small and dormant companies are exempt from the cash flow statement.
B19: Share capital
B20: Face value per equity share (Rs) | C20: 10
B21: Authorised equity shares (number) | C21: 1000000
B22: Issued and paid-up shares - current year end | C22: 500000
B23: Issued and paid-up shares - previous year end | C23: 500000
B24: Preference dividend incl tax, if any (Rs) | C24: 0
B26: Rounding divisor (auto) | C26: =IF(C14="Actual",1,IF(C14="Hundreds",100,IF(C14="Thousands",1000,IF(C14="Lakhs",100000,IF(C14="Millions",1000000,10000000)))))
B27: Units caption (auto) | C27: ="Amounts in Rs "&IF(C14="Actual","",C14)
B29: Signatories (printed under each statement)
B30: Audit firm name | C30: M/s XYZ & Associates
B31: Firm registration number | C31: 012345S
B32: Partner name | C32: CA Partner Name
B33: Partner membership number | C33: 123456
B34: UDIN
B35: Director 1 name | C35: Director One
B36: Director 1 DIN | C36: 01234567
B37: Director 2 name | C37: Director Two
B38: Director 2 DIN | C38: 07654321
B39: Place | C39: Hyderabad
B40: Date of signing
B41: Auditor designation | C41: Proprietor
B42: Director 1 designation | C42: Director
B43: Director 2 designation | C43: Director

Sheet Map Guide
B2: Map codes - tagging guide
B3: One TB row = one ledger. Pick the code that says WHERE the ledger belongs; the ledger name itself becomes the line inside the note. Paste debits in the Debit column and credits in the Credit column exactly as in your TB - no signs needed.
B4: Golden rules: (1) tag every ledger separately - each one prints as its own note line; (2) map the FULL closing balance of term loans to LTB - the workbook moves the 12-month portion to Short-term borrowings itself; (3) RS is the OPENING surplus/reserves only - the year profit is added automatically; (4) CHGINV is opening minus closing stock of FG/WIP (credit balance when stock has grown).
B6: Code | C6: Use it for | D6: Typical ledgers you would tag | E6: Lands on
B7: EQUITY AND LIABILITIES
B8: SC | C8: Share capital | D8: Equity share capital, preference share capital | E8: BS 1(a) - Note 2
B9: RS | C9: Reserves and surplus - OPENING balances | D9: Surplus in P&L (opening), general reserve, securities premium, capital reserve | E9: BS 1(b) - Note 3
B10: LTB | C10: Long-term borrowings - FULL loan balances | D10: Term loans, vehicle loans, housing loans, unsecured/director loans (long term) | E10: BS 2(a) and 3(a) - Notes 4 and 8
B11: DTL | C11: Deferred tax liability | D11: Deferred tax liability (net) | E11: BS 2(b) - Note 5
B12: OLTL | C12: Other long-term liabilities | D12: Trade/security deposits received, long-term customer advances | E12: BS 2(c) - Note 6
B13: LTPROV | C13: Long-term provisions | D13: Provision for gratuity / leave encashment (long-term portion) | E13: BS 2(d) - Note 7
B14: STB | C14: Short-term borrowings (repayable on demand) | D14: Cash credit, overdraft, WCDL, short-term loans | E14: BS 3(a) - Note 8
B15: TPMS | C15: Trade payables - micro and small (MSME) | D15: Creditors holding Udyam registration (micro/small) | E15: BS 3(b)(A) - Note 9
B16: TPOTH | C16: Trade payables - others | D16: All other sundry creditors for goods and services | E16: BS 3(b)(B) - Note 9
B17: OCL | C17: Other current liabilities | D17: GST/TDS/PF payable, expenses payable, advances from customers, interest accrued | E17: BS 3(c) - Note 10
B18: STPROV | C18: Short-term provisions | D18: Provision for income tax, proposed dividend, short-term employee provisions | E18: BS 3(d) - Note 11
B19: ASSETS
B20: PPE | C20: Property, plant and equipment (net block) | D20: Buildings, plant and machinery, furniture, vehicles, computers - net of depreciation | E20: BS 1(a) - Note 12
B21: INTAN | C21: Intangible assets (net) | D21: Software, patents, trademarks, goodwill - net of amortisation | E21: BS 1(b) - Note 12
B22: CWIP | C22: Capital work-in-progress | D22: Building/plant under construction | E22: BS 1(c) - Note 12
B23: IUD | C23: Intangibles under development | D23: Software under development | E23: BS 1(d) - Note 12
B24: NCINV | C24: Non-current investments | D24: Shares, mutual funds, property held long term | E24: BS 1(e) - Note 13
B25: DTA | C25: Deferred tax asset | D25: Deferred tax asset (net) | E25: BS 1(f) - Note 5
B26: LTLA | C26: Long-term loans and advances | D26: Security deposits given, capital advances, long-term staff loans | E26: BS 1(g) - Note 14
B27: ONCA | C27: Other non-current assets | D27: Long-term trade receivables, unamortised expenses | E27: BS 1(h) - Note 14
B28: CINV | C28: Current investments | D28: Liquid/short-term mutual funds | E28: BS 2(a) - Note 13A
B29: INVTY | C29: Inventories | D29: Raw materials, WIP, finished goods, stock-in-trade, stores and spares | E29: BS 2(b) - Note 15
B30: TR | C30: Trade receivables | D30: Sundry debtors (fill the Ageing sheet too) | E30: BS 2(c) - Note 16
B31: CASH | C31: Cash and cash equivalents | D31: Cash in hand, bank current accounts, deposits under 3 months | E31: BS 2(d) - Note 17
... B33: OCA | C33: Other current assets | D33: Prepaid expenses, accrued income, GST/income-tax refundable | E33: BS 2(f) - Note 14B
B34: STATEMENT OF PROFIT AND LOSS
B35: REV | C35: Revenue from operations | D35: Sales, service income, job-work income - each stream as its own ledger | E35: P&L I - Note 18
B36: OTHINC | C36: Other income | D36: Interest received, dividend, discount received, misc income | E36: P&L II - Note 19
B37: MATCONS | C37: Cost of materials consumed | D37: Raw material consumed (derivation grid in Note 20) | E37: P&L IV - Note 20
B38: PURST | C38: Purchases of stock-in-trade | D38: Purchases for resale (trading goods) | E38: P&L IV
B39: CHGINV | C39: Changes in inventories | D39: Opening minus closing stock of FG/WIP/stock-in-trade | E39: P&L IV
B40: EMPB | C40: Employee benefits expense | D40: Salaries and wages, bonus, PF/ESI contribution, staff welfare, gratuity | E40: P&L IV - Note 21
B41: FINC | C41: Finance costs | D41: Interest on term loans/CC, loan processing fees, interest on statutory delays | E41: P&L IV - Note 22
B42: DEPAM | C42: Depreciation and amortisation | D42: Depreciation, amortisation of software | E42: P&L IV - Note 12
B43: OTHEXP | C43: Other expenses | D43: Rent, audit fee, consulting charges, ROC fees, pooja expenses, business promotion, travel, repairs, insurance, power, bank charges - EACH as its own ledger row | E43: P&L IV - Note 23
...

Sheet Map
A1: Code | B1: Maps to | C1: Class
A2: SC | B2: Share capital | C2: L
A3: RS | B3: Reserves and surplus (opening) | C3: L
A4: LTB | B4: Long-term borrowings (full loan balances) | C4: L
A5: DTL | B5: Deferred tax liability | C5: L
A6: OLTL | B6: Other long-term liabilities | C6: L
A7: LTPROV | B7: Long-term provisions | C7: L
A8: STB | B8: Short-term borrowings (CC/OD/demand) | C8: L
A9: TPMS | B9: Trade payables - MSME | C9: L
A10: TPOTH | B10: Trade payables - others | C10: L
A11: OCL | B11: Other current liabilities | C11: L
A12: STPROV | B12: Short-term provisions | C12: L
... A38: TAXDEF | B38: Deferred tax (charge +ve / credit -ve) | C38: E

Sheet TB
A2: Trial Balance - paste and map
A3: Paste account heads with CY and PY closing balances IN RUPEES, then pick a Map code for every row (dropdown). P&L balances included (pre-closing TB). Reserves = OPENING reserves; the workbook adds the year profit itself.
A4: New to the codes? Open the Map Guide sheet - every code with typical ledgers and where it lands.
A5: Account head | B5: CY Debit | C5: CY Credit | D5: PY Debit | E5: PY Credit | F5: Map code | G5: Mapped to (auto) | H5: key
G6: =IF(F6="","",IFERROR(INDEX(Map!$B$2:$B$38,MATCH(F6,Map!$A$2:$A$38,0)),"UNKNOWN CODE")) | H6: =IF(F6="","",F6&"#"&COUNTIF($F$6:F6,F6))
G7: =IF(F7="","",IFERROR(INDEX(Map!$B$2:$B$38,MATCH(F7,Map!$A$2:$A$38,0)),"UNKNOWN CODE")) | H7: =IF(F7="","",F7&"#"&COUNTIF($F$6:F7,F7))
G8: =IF(F8="","",IFERROR(INDEX(Map!$B$2:$B$38,MATCH(F8,Map!$A$2:$A$38,0)),"UNKNOWN CODE")) | H8: =IF(F8="","",F8&"#"&COUNTIF($F$6:F8,F8))
G9: =IF(F9="","",IFERROR(INDEX(Map!$B$2:$B$38,MATCH(F9,Map!$A$2:$A$38,0)),"UNKNOWN CODE")) | H9: =IF(F9="","",F9&"#"&COUNTIF($F$6:F9,F9))
G10: =IF(F10="","",IFERROR(INDEX(Map!$B$2:$B$38,MATCH(F10,Map!$A$2:$A$38,0)),"UNKNOWN CODE")) | H10: =IF(F10="","",F10&"#"&COUNTIF($F$6:F10,F10))
G11: =IF(F11="","",IFERROR(INDEX(Map!$B$2:$B$38,MATCH(F11,Map!$A$2:$A$38,0)),"UNKNOWN CODE")) | H11: =IF(F11="","",F11&"#"&COUNTIF($F$6:F11,F11))
G12: =IF(F12="","",IFERROR(INDEX(Map!$B$2:$B$38,MATCH(F12,Map!$A$2:$A$38,0)),"UNKNOWN CODE")) | H12: =IF(F12="","",F12&"#"&COUNTIF($F$6:F12,F12))
G13: =IF(F13="","",IFERROR(INDEX(Map!$B$2:$B$38,MATCH(F13,Map!$A$2:$A$38,0)),"UNKNOWN CODE")) | H13: =IF(F13="","",F13&"#"&COUNTIF($F$6:F13,F13))
G14: =IF(F14="","",IFERROR(INDEX(Map!$B$2:$B$38,MATCH(F14,Map!$A$2:$A$38,0)),"UNKNOWN CODE")) | H14: =IF(F14="","",F14&"#"&COUNTIF($F$6:F14,F14))
G15: =IF(F15="","",IFERROR(INDEX(Map!$B$2:$B$38,MATCH(F15,Map!$A$2:$A$38,0)),"UNKNOWN CODE")) | H15: =IF(F15="","",F15&"#"&COUNTIF($F$6:F15,F15))
G16: =IF(F16="","",IFERROR(INDEX(Map!$B$2:$B$38,MATCH(F16,Map!$A$2:$A$38,0)),"UNKNOWN CODE")) | H16: =IF(F16="","",F16&"#"&COUNTIF($F$6:F16,F16))
G17: =IF(F17="","",IFERROR(INDEX(Map!$B$2:$B$38,MATCH(F17,Map!$A$2:$A$38,0)),"UNKNOWN CODE")) | H17: =IF(F17="","",F17&"#"&COUNTIF($F$6:F17,F17))
... G225: =IF(F225="","",IFERROR(INDEX(Map!$B$2:$B$38,MATCH(F225,Map!$A$2:$A$38,0)),"UNKNOWN CODE")) | H225: =IF(F225="","",F225&"#"&COUNTIF($F$6:F225,F225))
A226: Totals | B226: =SUM(B6:B225) | C226: =SUM(C6:C225) | D226: =SUM(D6:D225) | E226: =SUM(E6:E225)
A227: Difference (must be zero) | B227: =B226-C226 | D227: =D226-E226
A228: Rows with amounts but no map code | B228: =SUMPRODUCT(((B6:B225<>0)+(C6:C225<>0)+(D6:D225<>0)+(E6:E225<>0)>0)*(F6:F225=""))

Sheet Calc
A1: code | B1: CY netDr | C1: PY netDr
A2: SC | B2: =SUMIF(TB!$F$6:$F$225,A2,TB!$B$6:$B$225)-SUMIF(TB!$F$6:$F$225,A2,TB!$C$6:$C$225) | C2: =SUMIF(TB!$F$6:$F$225,A2,TB!$D$6:$D$225)-SUMIF(TB!$F$6:$F$225,A2,TB!$E$6:$E$225)
A3: RS | B3: =SUMIF(TB!$F$6:$F$225,A3,TB!$B$6:$B$225)-SUMIF(TB!$F$6:$F$225,A3,TB!$C$6:$C$225) | C3: =SUMIF(TB!$F$6:$F$225,A3,TB!$D$6:$D$225)-SUMIF(TB!$F$6:$F$225,A3,TB!$E$6:$E$225)
A4: LTB | B4: =SUMIF(TB!$F$6:$F$225,A4,TB!$B$6:$B$225)-SUMIF(TB!$F$6:$F$225,A4,TB!$C$6:$C$225) | C4: =SUMIF(TB!$F$6:$F$225,A4,TB!$D$6:$D$225)-SUMIF(TB!$F$6:$F$225,A4,TB!$E$6:$E$225)
A5: DTL | B5: =SUMIF(TB!$F$6:$F$225,A5,TB!$B$6:$B$225)-SUMIF(TB!$F$6:$F$225,A5,TB!$C$6:$C$225) | C5: =SUMIF(TB!$F$6:$F$225,A5,TB!$D$6:$D$225)-SUMIF(TB!$F$6:$F$225,A5,TB!$E$6:$E$225)
A6: OLTL | B6: =SUMIF(TB!$F$6:$F$225,A6,TB!$B$6:$B$225)-SUMIF(TB!$F$6:$F$225,A6,TB!$C$6:$C$225) | C6: =SUMIF(TB!$F$6:$F$225,A6,TB!$D$6:$D$225)-SUMIF(TB!$F$6:$F$225,A6,TB!$E$6:$E$225)
A7: LTPROV | B7: =SUMIF(TB!$F$6:$F$225,A7,TB!$B$6:$B$225)-SUMIF(TB!$F$6:$F$225,A7,TB!$C$6:$C$225) | C7: =SUMIF(TB!$F$6:$F$225,A7,TB!$D$6:$D$225)-SUMIF(TB!$F$6:$F$225,A7,TB!$E$6:$E$225)
A8: STB | B8: =SUMIF(TB!$F$6:$F$225,A8,TB!$B$6:$B$225)-SUMIF(TB!$F$6:$F$225,A8,TB!$C$6:$C$225) | C8: =SUMIF(TB!$F$6:$F$225,A8,TB!$D$6:$D$225)-SUMIF(TB!$F$6:$F$225,A8,TB!$E$6:$E$225)
A9: TPMS | B9: =SUMIF(TB!$F$6:$F$225,A9,TB!$B$6:$B$225)-SUMIF(TB!$F$6:$F$225,A9,TB!$C$6:$C$225) | C9: =SUMIF(TB!$F$6:$F$225,A9,TB!$D$6:$D$225)-SUMIF(TB!$F$6:$F$225,A9,TB!$E$6:$E$225)
A10: TPOTH | B10: =SUMIF(TB!$F$6:$F$225,A10,TB!$B$6:$B$225)-SUMIF(TB!$F$6:$F$225,A10,TB!$C$6:$C$225) | C10: =SUMIF(TB!$F$6:$F$225,A10,TB!$D$6:$D$225)-SUMIF(TB!$F$6:$F$225,A10,TB!$E$6:$E$225)
A11: OCL | B11: =SUMIF(TB!$F$6:$F$225,A11,TB!$B$6:$B$225)-SUMIF(TB!$F$6:$F$225,A11,TB!$C$6:$C$225) | C11: =SUMIF(TB!$F$6:$F$225,A11,TB!$D$6:$D$225)-SUMIF(TB!$F$6:$F$225,A11,TB!$E$6:$E$225)
A12: STPROV | B12: =SUMIF(TB!$F$6:$F$225,A12,TB!$B$6:$B$225)-SUMIF(TB!$F$6:$F$225,A12,TB!$C$6:$C$225) | C12: =SUMIF(TB!$F$6:$F$225,A12,TB!$D$6:$D$225)-SUMIF(TB!$F$6:$F$225,A12,TB!$E$6:$E$225)
A13: PPE | B13: =SUMIF(TB!$F$6:$F$225,A13,TB!$B$6:$B$225)-SUMIF(TB!$F$6:$F$225,A13,TB!$C$6:$C$225) | C13: =SUMIF(TB!$F$6:$F$225,A13,TB!$D$6:$D$225)-SUMIF(TB!$F$6:$F$225,A13,TB!$E$6:$E$225)
... A38: TAXDEF | B38: =SUMIF(TB!$F$6:$F$225,A38,TB!$B$6:$B$225)-SUMIF(TB!$F$6:$F$225,A38,TB!$C$6:$C$225) | C38: =SUMIF(TB!$F$6:$F$225,A38,TB!$D$6:$D$225)-SUMIF(TB!$F$6:$F$225,A38,TB!$E$6:$E$225)
A45: PAT_CY | B45: =-(Calc!$B$27+Calc!$B$28)-(Calc!$B$29+Calc!$B$30+Calc!$B$31+Calc!$B$32+Calc!$B$33+Calc!$B$34+Calc!$B$35+Calc!$B$36+Calc!$B$37+Calc!$B$38)
A46: PAT_PY | C46: =-(Calc!$C$27+Calc!$C$28)-(Calc!$C$29+Calc!$C$30+Calc!$C$31+Calc!$C$32+Calc!$C$33+Calc!$C$34+Calc!$C$35+Calc!$C$36+Calc!$C$37+Calc!$C$38)

Sheet Borrowings
A2: Long-term borrowings - loan grid and current-maturities split
A3: Enter every long-term loan at its CLOSING principal on the balance sheet date. Map the SAME balances to code LTB in the TB. The workbook computes the principal due within 12 months (current maturities) and moves it under Short-term borrowings on the face, per the 2021 amendment.
A5: Lender / loan | B5: Secured? | C5: Nature of security | D5: Rate % p.a. | E5: Repayment type | F5: EMI / monthly principal (Rs) | G5: Maturity date (bullet) | H5: Months left (info) | I5: Outstanding at BS date (Rs) | J5: Current maturities (auto, Rs) | K5: Non-current (auto, Rs) | L5: Interest accrued but not due (Rs)
B6: No | E6: EMI | H6: =IF(I6=0,"",IF(E6="Bullet",IF(G6="","?",ROUND((G6-BSD)/30.4,0)),IF(F6=0,"?",IF(E6="EMI",IFERROR(ROUND(LN(F6/(F6-I6*D6/1200))/LN(1+D6/1200),0),"?"),ROUND(I6/F6,0))))) | J6: =IF(I6=0,0,IF(E6="Bullet",IF(G6="",0,IF(G6<=BSD+366,I6,0)),IF(E6="Equal principal",MIN(I6,F6*12),IF(D6=0,MIN(I6,F6*12),MIN(I6,MAX(0,I6-MAX(0,I6*POWER(1+D6/1200,12)-F6*((POWER(1+D6/1200,12)-1)/(D6/1200))))))))) | K6: =I6-J6 | L6: 0
B7: No | E7: EMI | H7: =IF(I7=0,"",IF(E7="Bullet",IF(G7="","?",ROUND((G7-BSD)/30.4,0)),IF(F7=0,"?",IF(E7="EMI",IFERROR(ROUND(LN(F7/(F7-I7*D7/1200))/LN(1+D7/1200),0),"?"),ROUND(I7/F7,0))))) | J7: =IF(I7=0,0,IF(E7="Bullet",IF(G7="",0,IF(G7<=BSD+366,I7,0)),IF(E7="Equal principal",MIN(I7,F7*12),IF(D7=0,MIN(I7,F7*12),MIN(I7,MAX(0,I7-MAX(0,I7*POWER(1+D7/1200,12)-F7*((POWER(1+D7/1200,12)-1)/(D7/1200))))))))) | K7: =I7-J7 | L7: 0
B8: No | E8: EMI | H8: =IF(I8=0,"",IF(E8="Bullet",IF(G8="","?",ROUND((G8-BSD)/30.4,0)),IF(F8=0,"?",IF(E8="EMI",IFERROR(ROUND(LN(F8/(F8-I8*D8/1200))/LN(1+D8/1200),0),"?"),ROUND(I8/F8,0))))) | J8: =IF(I8=0,0,IF(E8="Bullet",IF(G8="",0,IF(G8<=BSD+366,I8,0)),IF(E8="Equal principal",MIN(I8,F8*12),IF(D8=0,MIN(I8,F8*12),MIN(I8,MAX(0,I8-MAX(0,I8*POWER(1+D8/1200,12)-F8*((POWER(1+D8/1200,12)-1)/(D8/1200))))))))) | K8: =I8-J8 | L8: 0
B9: No | E9: EMI | H9: =IF(I9=0,"",IF(E9="Bullet",IF(G9="","?",ROUND((G9-BSD)/30.4,0)),IF(F9=0,"?",IF(E9="EMI",IFERROR(ROUND(LN(F9/(F9-I9*D9/1200))/LN(1+D9/1200),0),"?"),ROUND(I9/F9,0))))) | J9: =IF(I9=0,0,IF(E9="Bullet",IF(G9="",0,IF(G9<=BSD+366,I9,0)),IF(E9="Equal principal",MIN(I9,F9*12),IF(D9=0,MIN(I9,F9*12),MIN(I9,MAX(0,I9-MAX(0,I9*POWER(1+D9/1200,12)-F9*((POWER(1+D9/1200,12)-1)/(D9/1200))))))))) | K9: =I9-J9 | L9: 0
B10: No | E10: EMI | H10: =IF(I10=0,"",IF(E10="Bullet",IF(G10="","?",ROUND((G10-BSD)/30.4,0)),IF(F10=0,"?",IF(E10="EMI",IFERROR(ROUND(LN(F10/(F10-I10*D10/1200))/LN(1+D10/1200),0),"?"),ROUND(I10/F10,0))))) | J10: =IF(I10=0,0,IF(E10="Bullet",IF(G10="",0,IF(G10<=BSD+366,I10,0)),IF(E10="Equal principal",MIN(I10,F10*12),IF(D10=0,MIN(I10,F10*12),MIN(I10,MAX(0,I10-MAX(0,I10*POWER(1+D10/1200,12)-F10*((POWER(1+D10/1200,12)-1)/(D10/1200))))))))) | K10: =I10-J10 | L10: 0
B11: No | E11: EMI | H11: =IF(I11=0,"",IF(E11="Bullet",IF(G11="","?",ROUND((G11-BSD)/30.4,0)),IF(F11=0,"?",IF(E11="EMI",IFERROR(ROUND(LN(F11/(F11-I11*D11/1200))/LN(1+D11/1200),0),"?"),ROUND(I11/F11,0))))) | J11: =IF(I11=0,0,IF(E11="Bullet",IF(G11="",0,IF(G11<=BSD+366,I11,0)),IF(E11="Equal principal",MIN(I11,F11*12),IF(D11=0,MIN(I11,F11*12),MIN(I11,MAX(0,I11-MAX(0,I11*POWER(1+D11/1200,12)-F11*((POWER(1+D11/1200,12)-1)/(D11/1200))))))))) | K11: =I11-J11 | L11: 0
B12: No | E12: EMI | H12: =IF(I12=0,"",IF(E12="Bullet",IF(G12="","?",ROUND((G12-BSD)/30.4,0)),IF(F12=0,"?",IF(E12="EMI",IFERROR(ROUND(LN(F12/(F12-I12*D12/1200))/LN(1+D12/1200),0),"?"),ROUND(I12/F12,0))))) | J12: =IF(I12=0,0,IF(E12="Bullet",IF(G12="",0,IF(G12<=BSD+366,I12,0)),IF(E12="Equal principal",MIN(I12,F12*12),IF(D12=0,MIN(I12,F12*12),MIN(I12,MAX(0,I12-MAX(0,I12*POWER(1+D12/1200,12)-F12*((POWER(1+D12/1200,12)-1)/(D12/1200))))))))) | K12: =I12-J12 | L12: 0
B13: No | E13: EMI | H13: =IF(I13=0,"",IF(E13="Bullet",IF(G13="","?",ROUND((G13-BSD)/30.4,0)),IF(F13=0,"?",IF(E13="EMI",IFERROR(ROUND(LN(F13/(F13-I13*D13/1200))/LN(1+D13/1200),0),"?"),ROUND(I13/F13,0))))) | J13: =IF(I13=0,0,IF(E13="Bullet",IF(G13="",0,IF(G13<=BSD+366,I13,0)),IF(E13="Equal principal",MIN(I13,F13*12),IF(D13=0,MIN(I13,F13*12),MIN(I13,MAX(0,I13-MAX(0,I13*POWER(1+D13/1200,12)-F13*((POWER(1+D13/1200,12)-1)/(D13/1200))))))))) | K13: =I13-J13 | L13: 0
B14: No | E14: EMI | H14: =IF(I14=0,"",IF(E14="Bullet",IF(G14="","?",ROUND((G14-BSD)/30.4,0)),IF(F14=0,"?",IF(E14="EMI",IFERROR(ROUND(LN(F14/(F14-I14*D14/1200))/LN(1+D14/1200),0),"?"),ROUND(I14/F14,0))))) | J14: =IF(I14=0,0,IF(E14="Bullet",IF(G14="",0,IF(G14<=BSD+366,I14,0)),IF(E14="Equal principal",MIN(I14,F14*12),IF(D14=0,MIN(I14,F14*12),MIN(I14,MAX(0,I14-MAX(0,I14*POWER(1+D14/1200,12)-F14*((POWER(1+D14/1200,12)-1)/(D14/1200))))))))) | K14: =I14-J14 | L14: 0
B15: No | E15: EMI | H15: =IF(I15=0,"",IF(E15="Bullet",IF(G15="","?",ROUND((G15-BSD)/30.4,0)),IF(F15=0,"?",IF(E15="EMI",IFERROR(ROUND(LN(F15/(F15-I15*D15/1200))/LN(1+D15/1200),0),"?"),ROUND(I15/F15,0))))) | J15: =IF(I15=0,0,IF(E15="Bullet",IF(G15="",0,IF(G15<=BSD+366,I15,0)),IF(E15="Equal principal",MIN(I15,F15*12),IF(D15=0,MIN(I15,F15*12),MIN(I15,MAX(0,I15-MAX(0,I15*POWER(1+D15/1200,12)-F15*((POWER(1+D15/1200,12)-1)/(D15/1200))))))))) | K15: =I15-J15 | L15: 0
B16: No | E16: EMI | H16: =IF(I16=0,"",IF(E16="Bullet",IF(G16="","?",ROUND((G16-BSD)/30.4,0)),IF(F16=0,"?",IF(E16="EMI",IFERROR(ROUND(LN(F16/(F16-I16*D16/1200))/LN(1+D16/1200),0),"?"),ROUND(I16/F16,0))))) | J16: =IF(I16=0,0,IF(E16="Bullet",IF(G16="",0,IF(G16<=BSD+366,I16,0)),IF(E16="Equal principal",MIN(I16,F16*12),IF(D16=0,MIN(I16,F16*12),MIN(I16,MAX(0,I16-MAX(0,I16*POWER(1+D16/1200,12)-F16*((POWER(1+D16/1200,12)-1)/(D16/1200))))))))) | K16: =I16-J16 | L16: 0
B17: No | E17: EMI | H17: =IF(I17=0,"",IF(E17="Bullet",IF(G17="","?",ROUND((G17-BSD)/30.4,0)),IF(F17=0,"?",IF(E17="EMI",IFERROR(ROUND(LN(F17/(F17-I17*D17/1200))/LN(1+D17/1200),0),"?"),ROUND(I17/F17,0))))) | J17: =IF(I17=0,0,IF(E17="Bullet",IF(G17="",0,IF(G17<=BSD+366,I17,0)),IF(E17="Equal principal",MIN(I17,F17*12),IF(D17=0,MIN(I17,F17*12),MIN(I17,MAX(0,I17-MAX(0,I17*POWER(1+D17/1200,12)-F17*((POWER(1+D17/1200,12)-1)/(D17/1200))))))))) | K17: =I17-J17 | L17: 0
A18: Totals | I18: =SUM(I6:I17) | J18: =SUM(J6:J17) | K18: =SUM(K6:K17) | L18: =SUM(L6:L17)
A20: Check: grid outstanding vs TB code LTB | I20: =I18-(-Calc!$B$4) | J20: Must be zero
A22: Carry to Balance Sheet:
A23: Long-term borrowings (non-current) | I23: =K18
A24: Current maturities of long-term borrowings (under Short-term borrowings) | I24: =J18
A25: Interest accrued but not due (under Other current liabilities - ensure it is in your OCL balance) | I25: =L18
A27: Previous year current maturities (enter from last year FS, Rs) | I27: 0

Sheet FAR
A1: CalcGuru | Fixed Asset Register & Depreciation
A2: =Setup!C5 | D2: ="FY "&Setup!C8
A3: FY start | B3: =Setup!C11+1 | C3: FY end | D3: =Setup!C9 | E3: 180-day cutoff | F3: =Setup!C9-179 | G3: Residual % | H3: 5
A5: Enter one asset per row in the shaded (yellow) cells B–I. Grey/white columns are formulas — leave them. Class & block useful lives / rates are in the tables to the right (editable). | T5: Companies Act classes (Schedule II) | W5: Income-tax blocks (WDV)
A6: S.No | B6: Asset description | C6: Companies Act class | D6: Income-tax block | E6: Date put to use | F6: Cost (Rs) | G6: Acc. dep up to FY start (Rs) | H6: Date of sale (if sold) | I6: Sale value (Rs) | J6: Useful life (yrs) | K6: SLM annual dep (Rs) | L6: Days in year | M6: Dep for year — CoAct (Rs) | N6: Closing acc dep (Rs) | O6: Net block — CoAct (Rs) | P6: IT rate | Q6: Addition >180d (Rs) | R6: Addition <180d (Rs) | T6: Class | U6: Useful life (yrs) | W6: Block | X6: Rate
A7: =IF($F7="","",1) | B7: Dell laptops (5 nos) | C7: Computers | D7: Computers (incl software) | E7: 45823 | F7: 300000 | G7: 0 | J7: =IF($F7="","",IFERROR(VLOOKUP($C7,$T$7:$U$12,2,0),"")) | K7: =IF($F7="","",($F7*(1-$H$3/100))/$J7) | L7: =IF($F7="","",MIN(366,MAX(0,IF($H7="",$D$3,$H7)-MAX($E7,$B$3)+1))) | M7: =IF($F7="","",MIN($K7*$L7/365,($F7*(1-$H$3/100))-$G7)) | N7: =IF($F7="","",$G7+$M7) | O7: =IF($F7="","",$F7-$N7) | P7: =IF($F7="","",IFERROR(VLOOKUP($D7,$W$7:$X$12,2,0),"")) | Q7: =IF($F7="","",IF(AND($E7>=$B$3,$E7<=$F$3),$F7,0)) | R7: =IF($F7="","",IF(AND($E7>=$B$3,$E7>$F$3),$F7,0)) | T7: Buildings | U7: 30 | W7: Building | X7: 0.1
A8: =IF($F8="","",2) | B8: Factory shed | C8: Buildings | D8: Building | E8: 44287 | F8: 5000000 | G8: 600000 | J8: =IF($F8="","",IFERROR(VLOOKUP($C8,$T$7:$U$12,2,0),"")) | K8: =IF($F8="","",($F8*(1-$H$3/100))/$J8) | L8: =IF($F8="","",MIN(366,MAX(0,IF($H8="",$D$3,$H8)-MAX($E8,$B$3)+1))) | M8: =IF($F8="","",MIN($K8*$L8/365,($F8*(1-$H$3/100))-$G8)) | N8: =IF($F8="","",$G8+$M8) | O8: =IF($F8="","",$F8-$N8) | P8: =IF($F8="","",IFERROR(VLOOKUP($D8,$W$7:$X$12,2,0),"")) | Q8: =IF($F8="","",IF(AND($E8>=$B$3,$E8<=$F$3),$F8,0)) | R8: =IF($F8="","",IF(AND($E8>=$B$3,$E8>$F$3),$F8,0)) | T8: Plant and Machinery | U8: 15 | W8: Plant and Machinery | X8: 0.15
A9: =IF($F9="","",3) | J9: =IF($F9="","",IFERROR(VLOOKUP($C9,$T$7:$U$12,2,0),"")) | K9: =IF($F9="","",($F9*(1-$H$3/100))/$J9) | L9: =IF($F9="","",MIN(366,MAX(0,IF($H9="",$D$3,$H9)-MAX($E9,$B$3)+1))) | M9: =IF($F9="","",MIN($K9*$L9/365,($F9*(1-$H$3/100))-$G9)) | N9: =IF($F9="","",$G9+$M9) | O9: =IF($F9="","",$F9-$N9) | P9: =IF($F9="","",IFERROR(VLOOKUP($D9,$W$7:$X$12,2,0),"")) | Q9: =IF($F9="","",IF(AND($E9>=$B$3,$E9<=$F$3),$F9,0)) | R9: =IF($F9="","",IF(AND($E9>=$B$3,$E9>$F$3),$F9,0)) | T9: Furniture and Fixtures | U9: 10 | W9: Furniture and Fittings | X9: 0.1
A10: =IF($F10="","",4) | J10: =IF($F10="","",IFERROR(VLOOKUP($C10,$T$7:$U$12,2,0),"")) | K10: =IF($F10="","",($F10*(1-$H$3/100))/$J10) | L10: =IF($F10="","",MIN(366,MAX(0,IF($H10="",$D$3,$H10)-MAX($E10,$B$3)+1))) | M10: =IF($F10="","",MIN($K10*$L10/365,($F10*(1-$H$3/100))-$G10)) | N10: =IF($F10="","",$G10+$M10) | O10: =IF($F10="","",$F10-$N10) | P10: =IF($F10="","",IFERROR(VLOOKUP($D10,$W$7:$X$12,2,0),"")) | Q10: =IF($F10="","",IF(AND($E10>=$B$3,$E10<=$F$3),$F10,0)) | R10: =IF($F10="","",IF(AND($E10>=$B$3,$E10>$F$3),$F10,0)) | T10: Vehicles | U10: 8 | W10: Motor Vehicles | X10: 0.15
A11: =IF($F11="","",5) | J11: =IF($F11="","",IFERROR(VLOOKUP($C11,$T$7:$U$12,2,0),"")) | K11: =IF($F11="","",($F11*(1-$H$3/100))/$J11) | L11: =IF($F11="","",MIN(366,MAX(0,IF($H11="",$D$3,$H11)-MAX($E11,$B$3)+1))) | M11: =IF($F11="","",MIN($K11*$L11/365,($F11*(1-$H$3/100))-$G11)) | N11: =IF($F11="","",$G11+$M11) | O11: =IF($F11="","",$F11-$N11) | P11: =IF($F11="","",IFERROR(VLOOKUP($D11,$W$7:$X$12,2,0),"")) | Q11: =IF($F11="","",IF(AND($E11>=$B$3,$E11<=$F$3),$F11,0)) | R11: =IF($F11="","",IF(AND($E11>=$B$3,$E11>$F$3),$F11,0)) | T11: Office Equipment | U11: 5 | W11: Computers (incl software) | X11: 0.4
A12: =IF($F12="","",6) | J12: =IF($F12="","",IFERROR(VLOOKUP($C12,$T$7:$U$12,2,0),"")) | K12: =IF($F12="","",($F12*(1-$H$3/100))/$J12) | L12: =IF($F12="","",MIN(366,MAX(0,IF($H12="",$D$3,$H12)-MAX($E12,$B$3)+1))) | M12: =IF($F12="","",MIN($K12*$L12/365,($F12*(1-$H$3/100))-$G12)) | N12: =IF($F12="","",$G12+$M12) | O12: =IF($F12="","",$F12-$N12) | P12: =IF($F12="","",IFERROR(VLOOKUP($D12,$W$7:$X$12,2,0),"")) | Q12: =IF($F12="","",IF(AND($E12>=$B$3,$E12<=$F$3),$F12,0)) | R12: =IF($F12="","",IF(AND($E12>=$B$3,$E12>$F$3),$F12,0)) | T12: Computers | U12: 3 | W12: Intangible assets | X12: 0.25
A13: =IF($F13="","",7) | J13: =IF($F13="","",IFERROR(VLOOKUP($C13,$T$7:$U$12,2,0),"")) | K13: =IF($F13="","",($F13*(1-$H$3/100))/$J13) | L13: =IF($F13="","",MIN(366,MAX(0,IF($H13="",$D$3,$H13)-MAX($E13,$B$3)+1))) | M13: =IF($F13="","",MIN($K13*$L13/365,($F13*(1-$H$3/100))-$G13)) | N13: =IF($F13="","",$G13+$M13) | O13: =IF($F13="","",$F13-$N13) | P13: =IF($F13="","",IFERROR(VLOOKUP($D13,$W$7:$X$12,2,0),"")) | Q13: =IF($F13="","",IF(AND($E13>=$B$3,$E13<=$F$3),$F13,0)) | R13: =IF($F13="","",IF(AND($E13>=$B$3,$E13>$F$3),$F13,0))
A14: =IF($F14="","",8) | J14: =IF($F14="","",IFERROR(VLOOKUP($C14,$T$7:$U$12,2,0),"")) | K14: =IF($F14="","",($F14*(1-$H$3/100))/$J14) | L14: =IF($F14="","",MIN(366,MAX(0,IF($H14="",$D$3,$H14)-MAX($E14,$B$3)+1))) | M14: =IF($F14="","",MIN($K14*$L14/365,($F14*(1-$H$3/100))-$G14)) | N14: =IF($F14="","",$G14+$M14) | O14: =IF($F14="","",$F14-$N14) | P14: =IF($F14="","",IFERROR(VLOOKUP($D14,$W$7:$X$12,2,0),"")) | Q14: =IF($F14="","",IF(AND($E14>=$B$3,$E14<=$F$3),$F14,0)) | R14: =IF($F14="","",IF(AND($E14>=$B$3,$E14>$F$3),$F14,0))
A15: =IF($F15="","",9) | J15: =IF($F15="","",IFERROR(VLOOKUP($C15,$T$7:$U$12,2,0),"")) | K15: =IF($F15="","",($F15*(1-$H$3/100))/$J15) | L15: =IF($F15="","",MIN(366,MAX(0,IF($H15="",$D$3,$H15)-MAX($E15,$B$3)+1))) | M15: =IF($F15="","",MIN($K15*$L15/365,($F15*(1-$H$3/100))-$G15)) | N15: =IF($F15="","",$G15+$M15) | O15: =IF($F15="","",$F15-$N15) | P15: =IF($F15="","",IFERROR(VLOOKUP($D15,$W$7:$X$12,2,0),"")) | Q15: =IF($F15="","",IF(AND($E15>=$B$3,$E15<=$F$3),$F15,0)) | R15: =IF($F15="","",IF(AND($E15>=$B$3,$E15>$F$3),$F15,0))
A16: =IF($F16="","",10) | J16: =IF($F16="","",IFERROR(VLOOKUP($C16,$T$7:$U$12,2,0),"")) | K16: =IF($F16="","",($F16*(1-$H$3/100))/$J16) | L16: =IF($F16="","",MIN(366,MAX(0,IF($H16="",$D$3,$H16)-MAX($E16,$B$3)+1))) | M16: =IF($F16="","",MIN($K16*$L16/365,($F16*(1-$H$3/100))-$G16)) | N16: =IF($F16="","",$G16+$M16) | O16: =IF($F16="","",$F16-$N16) | P16: =IF($F16="","",IFERROR(VLOOKUP($D16,$W$7:$X$12,2,0),"")) | Q16: =IF($F16="","",IF(AND($E16>=$B$3,$E16<=$F$3),$F16,0)) | R16: =IF($F16="","",IF(AND($E16>=$B$3,$E16>$F$3),$F16,0))
A17: =IF($F17="","",11) | J17: =IF($F17="","",IFERROR(VLOOKUP($C17,$T$7:$U$12,2,0),"")) | K17: =IF($F17="","",($F17*(1-$H$3/100))/$J17) | L17: =IF($F17="","",MIN(366,MAX(0,IF($H17="",$D$3,$H17)-MAX($E17,$B$3)+1))) | M17: =IF($F17="","",MIN($K17*$L17/365,($F17*(1-$H$3/100))-$G17)) | N17: =IF($F17="","",$G17+$M17) | O17: =IF($F17="","",$F17-$N17) | P17: =IF($F17="","",IFERROR(VLOOKUP($D17,$W$7:$X$12,2,0),"")) | Q17: =IF($F17="","",IF(AND($E17>=$B$3,$E17<=$F$3),$F17,0)) | R17: =IF($F17="","",IF(AND($E17>=$B$3,$E17>$F$3),$F17,0))
A18: =IF($F18="","",12) | J18: =IF($F18="","",IFERROR(VLOOKUP($C18,$T$7:$U$12,2,0),"")) | K18: =IF($F18="","",($F18*(1-$H$3/100))/$J18) | L18: =IF($F18="","",MIN(366,MAX(0,IF($H18="",$D$3,$H18)-MAX($E18,$B$3)+1))) | M18: =IF($F18="","",MIN($K18*$L18/365,($F18*(1-$H$3/100))-$G18)) | N18: =IF($F18="","",$G18+$M18) | O18: =IF($F18="","",$F18-$N18) | P18: =IF($F18="","",IFERROR(VLOOKUP($D18,$W$7:$X$12,2,0),"")) | Q18: =IF($F18="","",IF(AND($E18>=$B$3,$E18<=$F$3),$F18,0)) | R18: =IF($F18="","",IF(AND($E18>=$B$3,$E18>$F$3),$F18,0))
A19: =IF($F19="","",13) | J19: =IF($F19="","",IFERROR(VLOOKUP($C19,$T$7:$U$12,2,0),"")) | K19: =IF($F19="","",($F19*(1-$H$3/100))/$J19) | L19: =IF($F19="","",MIN(366,MAX(0,IF($H19="",$D$3,$H19)-MAX($E19,$B$3)+1))) | M19: =IF($F19="","",MIN($K19*$L19/365,($F19*(1-$H$3/100))-$G19)) | N19: =IF($F19="","",$G19+$M19) | O19: =IF($F19="","",$F19-$N19) | P19: =IF($F19="","",IFERROR(VLOOKUP($D19,$W$7:$X$12,2,0),"")) | Q19: =IF($F19="","",IF(AND($E19>=$B$3,$E19<=$F$3),$F19,0)) | R19: =IF($F19="","",IF(AND($E19>=$B$3,$E19>$F$3),$F19,0))
A20: =IF($F20="","",14) | J20: =IF($F20="","",IFERROR(VLOOKUP($C20,$T$7:$U$12,2,0),"")) | K20: =IF($F20="","",($F20*(1-$H$3/100))/$J20) | L20: =IF($F20="","",MIN(366,MAX(0,IF($H20="",$D$3,$H20)-MAX($E20,$B$3)+1))) | M20: =IF($F20="","",MIN($K20*$L20/365,($F20*(1-$H$3/100))-$G20)) | N20: =IF($F20="","",$G20+$M20) | O20: =IF($F20="","",$F20-$N20) | P20: =IF($F20="","",IFERROR(VLOOKUP($D20,$W$7:$X$12,2,0),"")) | Q20: =IF($F20="","",IF(AND($E20>=$B$3,$E20<=$F$3),$F20,0)) | R20: =IF($F20="","",IF(AND($E20>=$B$3,$E20>$F$3),$F20,0))
A21: =IF($F21="","",15) | J21: =IF($F21="","",IFERROR(VLOOKUP($C21,$T$7:$U$12,2,0),"")) | K21: =IF($F21="","",($F21*(1-$H$3/100))/$J21) | L21: =IF($F21="","",MIN(366,MAX(0,IF($H21="",$D$3,$H21)-MAX($E21,$B$3)+1))) | M21: =IF($F21="","",MIN($K21*$L21/365,($F21*(1-$H$3/100))-$G21)) | N21: =IF($F21="","",$G21+$M21) | O21: =IF($F21="","",$F21-$N21) | P21: =IF($F21="","",IFERROR(VLOOKUP($D21,$W$7:$X$12,2,0),"")) | Q21: =IF($F21="","",IF(AND($E21>=$B$3,$E21<=$F$3),$F21,0)) | R21: =IF($F21="","",IF(AND($E21>=$B$3,$E21>$F$3),$F21,0))
A22: =IF($F22="","",16) | J22: =IF($F22="","",IFERROR(VLOOKUP($C22,$T$7:$U$12,2,0),"")) | K22: =IF($F22="","",($F22*(1-$H$3/100))/$J22) | L22: =IF($F22="","",MIN(366,MAX(0,IF($H22="",$D$3,$H22)-MAX($E22,$B$3)+1))) | M22: =IF($F22="","",MIN($K22*$L22/365,($F22*(1-$H$3/100))-$G22)) | N22: =IF($F22="","",$G22+$M22) | O22: =IF($F22="","",$F22-$N22) | P22: =IF($F22="","",IFERROR(VLOOKUP($D22,$W$7:$X$12,2,0),"")) | Q22: =IF($F22="","",IF(AND($E22>=$B$3,$E22<=$F$3),$F22,0)) | R22: =IF($F22="","",IF(AND($E22>=$B$3,$E22>$F$3),$F22,0))
A23: =IF($F23="","",17) | J23: =IF($F23="","",IFERROR(VLOOKUP($C23,$T$7:$U$12,2,0),"")) | K23: =IF($F23="","",($F23*(1-$H$3/100))/$J23) | L23: =IF($F23="","",MIN(366,MAX(0,IF($H23="",$D$3,$H23)-MAX($E23,$B$3)+1))) | M23: =IF($F23="","",MIN($K23*$L23/365,($F23*(1-$H$3/100))-$G23)) | N23: =IF($F23="","",$G23+$M23) | O23: =IF($F23="","",$F23-$N23) | P23: =IF($F23="","",IFERROR(VLOOKUP($D23,$W$7:$X$12,2,0),"")) | Q23: =IF($F23="","",IF(AND($E23>=$B$3,$E23<=$F$3),$F23,0)) | R23: =IF($F23="","",IF(AND($E23>=$B$3,$E23>$F$3),$F23,0))
A24: =IF($F24="","",18) | J24: =IF($F24="","",IFERROR(VLOOKUP($C24,$T$7:$U$12,2,0),"")) | K24: =IF($F24="","",($F24*(1-$H$3/100))/$J24) | L24: =IF($F24="","",MIN(366,MAX(0,IF($H24="",$D$3,$H24)-MAX($E24,$B$3)+1))) | M24: =IF($F24="","",MIN($K24*$L24/365,($F24*(1-$H$3/100))-$G24)) | N24: =IF($F24="","",$G24+$M24) | O24: =IF($F24="","",$F24-$N24) | P24: =IF($F24="","",IFERROR(VLOOKUP($D24,$W$7:$X$12,2,0),"")) | Q24: =IF($F24="","",IF(AND($E24>=$B$3,$E24<=$F$3),$F24,0)) | R24: =IF($F24="","",IF(AND($E24>=$B$3,$E24>$F$3),$F24,0))
A25: =IF($F25="","",19) | J25: =IF($F25="","",IFERROR(VLOOKUP($C25,$T$7:$U$12,2,0),"")) | K25: =IF($F25="","",($F25*(1-$H$3/100))/$J25) | L25: =IF($F25="","",MIN(366,MAX(0,IF($H25="",$D$3,$H25)-MAX($E25,$B$3)+1))) | M25: =IF($F25="","",MIN($K25*$L25/365,($F25*(1-$H$3/100))-$G25)) | N25: =IF($F25="","",$G25+$M25) | O25: =IF($F25="","",$F25-$N25) | P25: =IF($F25="","",IFERROR(VLOOKUP($D25,$W$7:$X$12,2,0),"")) | Q25: =IF($F25="","",IF(AND($E25>=$B$3,$E25<=$F$3),$F25,0)) | R25: =IF($F25="","",IF(AND($E25>=$B$3,$E25>$F$3),$F25,0))
A26: =IF($F26="","",20) | J26: =IF($F26="","",IFERROR(VLOOKUP($C26,$T$7:$U$12,2,0),"")) | K26: =IF($F26="","",($F26*(1-$H$3/100))/$J26) | L26: =IF($F26="","",MIN(366,MAX(0,IF($H26="",$D$3,$H26)-MAX($E26,$B$3)+1))) | M26: =IF($F26="","",MIN($K26*$L26/365,($F26*(1-$H$3/100))-$G26)) | N26: =IF($F26="","",$G26+$M26) | O26: =IF($F26="","",$F26-$N26) | P26: =IF($F26="","",IFERROR(VLOOKUP($D26,$W$7:$X$12,2,0),"")) | Q26: =IF($F26="","",IF(AND($E26>=$B$3,$E26<=$F$3),$F26,0)) | R26: =IF($F26="","",IF(AND($E26>=$B$3,$E26>$F$3),$F26,0))
A27: =IF($F27="","",21) | J27: =IF($F27="","",IFERROR(VLOOKUP($C27,$T$7:$U$12,2,0),"")) | K27: =IF($F27="","",($F27*(1-$H$3/100))/$J27) | L27: =IF($F27="","",MIN(366,MAX(0,IF($H27="",$D$3,$H27)-MAX($E27,$B$3)+1))) | M27: =IF($F27="","",MIN($K27*$L27/365,($F27*(1-$H$3/100))-$G27)) | N27: =IF($F27="","",$G27+$M27) | O27: =IF($F27="","",$F27-$N27) | P27: =IF($F27="","",IFERROR(VLOOKUP($D27,$W$7:$X$12,2,0),"")) | Q27: =IF($F27="","",IF(AND($E27>=$B$3,$E27<=$F$3),$F27,0)) | R27: =IF($F27="","",IF(AND($E27>=$B$3,$E27>$F$3),$F27,0))
A28: =IF($F28="","",22) | J28: =IF($F28="","",IFERROR(VLOOKUP($C28,$T$7:$U$12,2,0),"")) | K28: =IF($F28="","",($F28*(1-$H$3/100))/$J28) | L28: =IF($F28="","",MIN(366,MAX(0,IF($H28="",$D$3,$H28)-MAX($E28,$B$3)+1))) | M28: =IF($F28="","",MIN($K28*$L28/365,($F28*(1-$H$3/100))-$G28)) | N28: =IF($F28="","",$G28+$M28) | O28: =IF($F28="","",$F28-$N28) | P28: =IF($F28="","",IFERROR(VLOOKUP($D28,$W$7:$X$12,2,0),"")) | Q28: =IF($F28="","",IF(AND($E28>=$B$3,$E28<=$F$3),$F28,0)) | R28: =IF($F28="","",IF(AND($E28>=$B$3,$E28>$F$3),$F28,0))
A29: =IF($F29="","",23) | J29: =IF($F29="","",IFERROR(VLOOKUP($C29,$T$7:$U$12,2,0),"")) | K29: =IF($F29="","",($F29*(1-$H$3/100))/$J29) | L29: =IF($F29="","",MIN(366,MAX(0,IF($H29="",$D$3,$H29)-MAX($E29,$B$3)+1))) | M29: =IF($F29="","",MIN($K29*$L29/365,($F29*(1-$H$3/100))-$G29)) | N29: =IF($F29="","",$G29+$M29) | O29: =IF($F29="","",$F29-$N29) | P29: =IF($F29="","",IFERROR(VLOOKUP($D29,$W$7:$X$12,2,0),"")) | Q29: =IF($F29="","",IF(AND($E29>=$B$3,$E29<=$F$3),$F29,0)) | R29: =IF($F29="","",IF(AND($E29>=$B$3,$E29>$F$3),$F29,0))
A30: =IF($F30="","",24) | J30: =IF($F30="","",IFERROR(VLOOKUP($C30,$T$7:$U$12,2,0),"")) | K30: =IF($F30="","",($F30*(1-$H$3/100))/$J30) | L30: =IF($F30="","",MIN(366,MAX(0,IF($H30="",$D$3,$H30)-MAX($E30,$B$3)+1))) | M30: =IF($F30="","",MIN($K30*$L30/365,($F30*(1-$H$3/100))-$G30)) | N30: =IF($F30="","",$G30+$M30) | O30: =IF($F30="","",$F30-$N30) | P30: =IF($F30="","",IFERROR(VLOOKUP($D30,$W$7:$X$12,2,0),"")) | Q30: =IF($F30="","",IF(AND($E30>=$B$3,$E30<=$F$3),$F30,0)) | R30: =IF($F30="","",IF(AND($E30>=$B$3,$E30>$F$3),$F30,0))
A31: =IF($F31="","",25) | J31: =IF($F31="","",IFERROR(VLOOKUP($C31,$T$7:$U$12,2,0),"")) | K31: =IF($F31="","",($F31*(1-$H$3/100))/$J31) | L31: =IF($F31="","",MIN(366,MAX(0,IF($H31="",$D$3,$H31)-MAX($E31,$B$3)+1))) | M31: =IF($F31="","",MIN($K31*$L31/365,($F31*(1-$H$3/100))-$G31)) | N31: =IF($F31="","",$G31+$M31) | O31: =IF($F31="","",$F31-$N31) | P31: =IF($F31="","",IFERROR(VLOOKUP($D31,$W$7:$X$12,2,0),"")) | Q31: =IF($F31="","",IF(AND($E31>=$B$3,$E31<=$F$3),$F31,0)) | R31: =IF($F31="","",IF(AND($E31>=$B$3,$E31>$F$3),$F31,0))
A32: =IF($F32="","",26) | J32: =IF($F32="","",IFERROR(VLOOKUP($C32,$T$7:$U$12,2,0),"")) | K32: =IF($F32="","",($F32*(1-$H$3/100))/$J32) | L32: =IF($F32="","",MIN(366,MAX(0,IF($H32="",$D$3,$H32)-MAX($E32,$B$3)+1))) | M32: =IF($F32="","",MIN($K32*$L32/365,($F32*(1-$H$3/100))-$G32)) | N32: =IF($F32="","",$G32+$M32) | O32: =IF($F32="","",$F32-$N32) | P32: =IF($F32="","",IFERROR(VLOOKUP($D32,$W$7:$X$12,2,0),"")) | Q32: =IF($F32="","",IF(AND($E32>=$B$3,$E32<=$F$3),$F32,0)) | R32: =IF($F32="","",IF(AND($E32>=$B$3,$E32>$F$3),$F32,0))
A33: =IF($F33="","",27) | J33: =IF($F33="","",IFERROR(VLOOKUP($C33,$T$7:$U$12,2,0),"")) | K33: =IF($F33="","",($F33*(1-$H$3/100))/$J33) | L33: =IF($F33="","",MIN(366,MAX(0,IF($H33="",$D$3,$H33)-MAX($E33,$B$3)+1))) | M33: =IF($F33="","",MIN($K33*$L33/365,($F33*(1-$H$3/100))-$G33)) | N33: =IF($F33="","",$G33+$M33) | O33: =IF($F33="","",$F33-$N33) | P33: =IF($F33="","",IFERROR(VLOOKUP($D33,$W$7:$X$12,2,0),"")) | Q33: =IF($F33="","",IF(AND($E33>=$B$3,$E33<=$F$3),$F33,0)) | R33: =IF($F33="","",IF(AND($E33>=$B$3,$E33>$F$3),$F33,0))
A34: =IF($F34="","",28) | J34: =IF($F34="","",IFERROR(VLOOKUP($C34,$T$7:$U$12,2,0),"")) | K34: =IF($F34="","",($F34*(1-$H$3/100))/$J34) | L34: =IF($F34="","",MIN(366,MAX(0,IF($H34="",$D$3,$H34)-MAX($E34,$B$3)+1))) | M34: =IF($F34="","",MIN($K34*$L34/365,($F34*(1-$H$3/100))-$G34)) | N34: =IF($F34="","",$G34+$M34) | O34: =IF($F34="","",$F34-$N34) | P34: =IF($F34="","",IFERROR(VLOOKUP($D34,$W$7:$X$12,2,0),"")) | Q34: =IF($F34="","",IF(AND($E34>=$B$3,$E34<=$F$3),$F34,0)) | R34: =IF($F34="","",IF(AND($E34>=$B$3,$E34>$F$3),$F34,0))
A35: =IF($F35="","",29) | J35: =IF($F35="","",IFERROR(VLOOKUP($C35,$T$7:$U$12,2,0),"")) | K35: =IF($F35="","",($F35*(1-$H$3/100))/$J35) | L35: =IF($F35="","",MIN(366,MAX(0,IF($H35="",$D$3,$H35)-MAX($E35,$B$3)+1))) | M35: =IF($F35="","",MIN($K35*$L35/365,($F35*(1-$H$3/100))-$G35)) | N35: =IF($F35="","",$G35+$M35) | O35: =IF($F35="","",$F35-$N35) | P35: =IF($F35="","",IFERROR(VLOOKUP($D35,$W$7:$X$12,2,0),"")) | Q35: =IF($F35="","",IF(AND($E35>=$B$3,$E35<=$F$3),$F35,0)) | R35: =IF($F35="","",IF(AND($E35>=$B$3,$E35>$F$3),$F35,0))
A36: =IF($F36="","",30) | J36: =IF($F36="","",IFERROR(VLOOKUP($C36,$T$7:$U$12,2,0),"")) | K36: =IF($F36="","",($F36*(1-$H$3/100))/$J36) | L36: =IF($F36="","",MIN(366,MAX(0,IF($H36="",$D$3,$H36)-MAX($E36,$B$3)+1))) | M36: =IF($F36="","",MIN($K36*$L36/365,($F36*(1-$H$3/100))-$G36)) | N36: =IF($F36="","",$G36+$M36) | O36: =IF($F36="","",$F36-$N36) | P36: =IF($F36="","",IFERROR(VLOOKUP($D36,$W$7:$X$12,2,0),"")) | Q36: =IF($F36="","",IF(AND($E36>=$B$3,$E36<=$F$3),$F36,0)) | R36: =IF($F36="","",IF(AND($E36>=$B$3,$E36>$F$3),$F36,0))
A37: =IF($F37="","",31) | J37: =IF($F37="","",IFERROR(VLOOKUP($C37,$T$7:$U$12,2,0),"")) | K37: =IF($F37="","",($F37*(1-$H$3/100))/$J37) | L37: =IF($F37="","",MIN(366,MAX(0,IF($H37="",$D$3,$H37)-MAX($E37,$B$3)+1))) | M37: =IF($F37="","",MIN($K37*$L37/365,($F37*(1-$H$3/100))-$G37)) | N37: =IF($F37="","",$G37+$M37) | O37: =IF($F37="","",$F37-$N37) | P37: =IF($F37="","",IFERROR(VLOOKUP($D37,$W$7:$X$12,2,0),"")) | Q37: =IF($F37="","",IF(AND($E37>=$B$3,$E37<=$F$3),$F37,0)) | R37: =IF($F37="","",IF(AND($E37>=$B$3,$E37>$F$3),$F37,0))
A38: =IF($F38="","",32) | J38: =IF($F38="","",IFERROR(VLOOKUP($C38,$T$7:$U$12,2,0),"")) | K38: =IF($F38="","",($F38*(1-$H$3/100))/$J38) | L38: =IF($F38="","",MIN(366,MAX(0,IF($H38="",$D$3,$H38)-MAX($E38,$B$3)+1))) | M38: =IF($F38="","",MIN($K38*$L38/365,($F38*(1-$H$3/100))-$G38)) | N38: =IF($F38="","",$G38+$M38) | O38: =IF($F38="","",$F38-$N38) | P38: =IF($F38="","",IFERROR(VLOOKUP($D38,$W$7:$X$12,2,0),"")) | Q38: =IF($F38="","",IF(AND($E38>=$B$3,$E38<=$F$3),$F38,0)) | R38: =IF($F38="","",IF(AND($E38>=$B$3,$E38>$F$3),$F38,0))
A39: =IF($F39="","",33) | J39: =IF($F39="","",IFERROR(VLOOKUP($C39,$T$7:$U$12,2,0),"")) | K39: =IF($F39="","",($F39*(1-$H$3/100))/$J39) | L39: =IF($F39="","",MIN(366,MAX(0,IF($H39="",$D$3,$H39)-MAX($E39,$B$3)+1))) | M39: =IF($F39="","",MIN($K39*$L39/365,($F39*(1-$H$3/100))-$G39)) | N39: =IF($F39="","",$G39+$M39) | O39: =IF($F39="","",$F39-$N39) | P39: =IF($F39="","",IFERROR(VLOOKUP($D39,$W$7:$X$12,2,0),"")) | Q39: =IF($F39="","",IF(AND($E39>=$B$3,$E39<=$F$3),$F39,0)) | R39: =IF($F39="","",IF(AND($E39>=$B$3,$E39>$F$3),$F39,0))
A40: =IF($F40="","",34) | J40: =IF($F40="","",IFERROR(VLOOKUP($C40,$T$7:$U$12,2,0),"")) | K40: =IF($F40="","",($F40*(1-$H$3/100))/$J40) | L40: =IF($F40="","",MIN(366,MAX(0,IF($H40="",$D$3,$H40)-MAX($E40,$B$3)+1))) | M40: =IF($F40="","",MIN($K40*$L40/365,($F40*(1-$H$3/100))-$G40)) | N40: =IF($F40="","",$G40+$M40) | O40: =IF($F40="","",$F40-$N40) | P40: =IF($F40="","",IFERROR(VLOOKUP($D40,$W$7:$X$12,2,0),"")) | Q40: =IF($F40="","",IF(AND($E40>=$B$3,$E40<=$F$3),$F40,0)) | R40: =IF($F40="","",IF(AND($E40>=$B$3,$E40>$F$3),$F40,0))
A41: =IF($F41="","",35) | J41: =IF($F41="","",IFERROR(VLOOKUP($C41,$T$7:$U$12,2,0),"")) | K41: =IF($F41="","",($F41*(1-$H$3/100))/$J41) | L41: =IF($F41="","",MIN(366,MAX(0,IF($H41="",$D$3,$H41)-MAX($E41,$B$3)+1))) | M41: =IF($F41="","",MIN($K41*$L41/365,($F41*(1-$H$3/100))-$G41)) | N41: =IF($F41="","",$G41+$M41) | O41: =IF($F41="","",$F41-$N41) | P41: =IF($F41="","",IFERROR(VLOOKUP($D41,$W$7:$X$12,2,0),"")) | Q41: =IF($F41="","",IF(AND($E41>=$B$3,$E41<=$F$3),$F41,0)) | R41: =IF($F41="","",IF(AND($E41>=$B$3,$E41>$F$3),$F41,0))
...

Sheet Dep-IT
A1: Depreciation — Income-tax Act, 1961 (block WDV)
A2: =Setup!C5 | F2: ="AY "&(VALUE(LEFT(Setup!C8,4))+1)&"-"&(VALUE(LEFT(Setup!C8,4))+2)
A3: Opening WDV (yellow) = closing WDV from last year’s IT return. Additions pull from the Register (180-day rule applied). Figures in Rs.
A5: Block of assets | B5: Rate | C5: Opening WDV | D5: Additions ≥180d | E5: Additions <180d | F5: Sale / realisation | G5: Dep for year | H5: Closing WDV
A6: =FAR!$W$7 | B6: =FAR!$X$7 | C6: 4000000 | D6: =SUMIFS(FAR!$Q$7:$Q$46,FAR!$D$7:$D$46,$A6) | E6: =SUMIFS(FAR!$R$7:$R$46,FAR!$D$7:$D$46,$A6) | F6: =SUMIFS(FAR!$I$7:$I$46,FAR!$D$7:$D$46,$A6,FAR!$H$7:$H$46,"<>") | G6: =MAX(0,($C6+$D6-$F6)*$B6)+$E6*$B6/2 | H6: =MAX(0,$C6+$D6+$E6-$F6-$G6)
A7: =FAR!$W$8 | B7: =FAR!$X$8 | C7: 0 | D7: =SUMIFS(FAR!$Q$7:$Q$46,FAR!$D$7:$D$46,$A7) | E7: =SUMIFS(FAR!$R$7:$R$46,FAR!$D$7:$D$46,$A7) | F7: =SUMIFS(FAR!$I$7:$I$46,FAR!$D$7:$D$46,$A7,FAR!$H$7:$H$46,"<>") | G7: =MAX(0,($C7+$D7-$F7)*$B7)+$E7*$B7/2 | H7: =MAX(0,$C7+$D7+$E7-$F7-$G7)
A8: =FAR!$W$9 | B8: =FAR!$X$9 | C8: 0 | D8: =SUMIFS(FAR!$Q$7:$Q$46,FAR!$D$7:$D$46,$A8) | E8: =SUMIFS(FAR!$R$7:$R$46,FAR!$D$7:$D$46,$A8) | F8: =SUMIFS(FAR!$I$7:$I$46,FAR!$D$7:$D$46,$A8,FAR!$H$7:$H$46,"<>") | G8: =MAX(0,($C8+$D8-$F8)*$B8)+$E8*$B8/2 | H8: =MAX(0,$C8+$D8+$E8-$F8-$G8)
A9: =FAR!$W$10 | B9: =FAR!$X$10 | C9: 0 | D9: =SUMIFS(FAR!$Q$7:$Q$46,FAR!$D$7:$D$46,$A9) | E9: =SUMIFS(FAR!$R$7:$R$46,FAR!$D$7:$D$46,$A9) | F9: =SUMIFS(FAR!$I$7:$I$46,FAR!$D$7:$D$46,$A9,FAR!$H$7:$H$46,"<>") | G9: =MAX(0,($C9+$D9-$F9)*$B9)+$E9*$B9/2 | H9: =MAX(0,$C9+$D9+$E9-$F9-$G9)
A10: =FAR!$W$11 | B10: =FAR!$X$11 | C10: 0 | D10: =SUMIFS(FAR!$Q$7:$Q$46,FAR!$D$7:$D$46,$A10) | E10: =SUMIFS(FAR!$R$7:$R$46,FAR!$D$7:$D$46,$A10) | F10: =SUMIFS(FAR!$I$7:$I$46,FAR!$D$7:$D$46,$A10,FAR!$H$7:$H$46,"<>") | G10: =MAX(0,($C10+$D10-$F10)*$B10)+$E10*$B10/2 | H10: =MAX(0,$C10+$D10+$E10-$F10-$G10)
A11: =FAR!$W$12 | B11: =FAR!$X$12 | C11: 0 | D11: =SUMIFS(FAR!$Q$7:$Q$46,FAR!$D$7:$D$46,$A11) | E11: =SUMIFS(FAR!$R$7:$R$46,FAR!$D$7:$D$46,$A11) | F11: =SUMIFS(FAR!$I$7:$I$46,FAR!$D$7:$D$46,$A11,FAR!$H$7:$H$46,"<>") | G11: =MAX(0,($C11+$D11-$F11)*$B11)+$E11*$B11/2 | H11: =MAX(0,$C11+$D11+$E11-$F11-$G11)
A12: Total | C12: =SUM(C6:C11) | D12: =SUM(D6:D11) | E12: =SUM(E6:E11) | F12: =SUM(F6:F11) | G12: =SUM(G6:G11) | H12: =SUM(H6:H11)
A14: Note: half depreciation applies where an asset is used for less than 180 days. Where sale proceeds exceed the block’s value, the block ceases and a capital gain/(loss) arises — handle separately.

Sheet Deferred Tax
A1: Deferred Tax (AS 22)
A2: =Setup!C5 | F2: ="FY "&Setup!C8
A3: Tax rate % | B3: 25.168 | C3: (effective rate incl. surcharge & cess)
A5: Timing difference | B5: Carrying amount — Books (Rs) | C5: Base — Tax (Rs) | D5: Difference (Rs) | E5: Nature | F5: Deferred tax (Rs)
A6: Depreciation — WDV of block of assets | B6: ='Dep-CoAct'!$J$12 | C6: ='Dep-IT'!$H$12 | D6: =$B6-$C6 | E6: =IF($D6>0,"DTL",IF($D6<0,"DTA","-")) | F6: =$D6*$B$3/100
A7: Provision for doubtful debts | B7: 0 | C7: 0 | D7: =$B7-$C7 | E7: =IF($D7>0,"DTL",IF($D7<0,"DTA","-")) | F7: =$D7*$B$3/100
A8: Provision for gratuity / leave (43B / employee benefits) | B8: 0 | C8: 0 | D8: =$B8-$C8 | E8: =IF($D8>0,"DTL",IF($D8<0,"DTA","-")) | F8: =$D8*$B$3/100
A9: Expenses disallowed u/s 43B (unpaid statutory dues) | B9: 0 | C9: 0 | D9: =$B9-$C9 | E9: =IF($D9>0,"DTL",IF($D9<0,"DTA","-")) | F9: =$D9*$B$3/100
A10: Preliminary / deferred revenue expenditure | B10: 0 | C10: 0 | D10: =$B10-$C10 | E10: =IF($D10>0,"DTL",IF($D10<0,"DTA","-")) | F10: =$D10*$B$3/100
A11: Others | B11: 0 | C11: 0 | D11: =$B11-$C11 | E11: =IF($D11>0,"DTL",IF($D11<0,"DTA","-")) | F11: =$D11*$B$3/100
A12: Net deferred tax liability / (asset) | D12: =SUM(D6:D11) | F12: =SUM(F6:F11)
A14: A positive net figure is a Deferred Tax Liability; a negative figure is a Deferred Tax Asset. The depreciation line is auto (Companies Act net block vs Income-tax WDV); enter the other timing differences in the yellow cells.
A16: Feeds Note 5 (Deferred tax) — the depreciation timing difference and rate carry into the notes automatically.

Sheet EPS
A2: Earnings per share (AS 20) - working
A3: Weighted average by days over the year to the balance sheet date. For bonus/split during or after the year, enter the retrospective factor (e.g. 1:1 bonus = 2). Use the online tool for rights-issue TERP: calcguru.in/eps-calculator-as-20/
A5: Opening equity shares (from Setup, PY closing) | B5: =Setup!C23
A6: Share issues (+) / buy-backs (-) during the year
A7: Event date | B7: Shares (+/-) | C7: Weighted (auto)
C8: =IF(OR(A8="",B8=0),0,B8*(BSD-A8+1)/(BSD-PBSD))
C9: =IF(OR(A9="",B9=0),0,B9*(BSD-A9+1)/(BSD-PBSD))
C10: =IF(OR(A10="",B10=0),0,B10*(BSD-A10+1)/(BSD-PBSD))
C11: =IF(OR(A11="",B11=0),0,B11*(BSD-A11+1)/(BSD-PBSD))
C12: =IF(OR(A12="",B12=0),0,B12*(BSD-A12+1)/(BSD-PBSD))
C13: =IF(OR(A13="",B13=0),0,B13*(BSD-A13+1)/(BSD-PBSD))
C14: =IF(OR(A14="",B14=0),0,B14*(BSD-A14+1)/(BSD-PBSD))
C15: =IF(OR(A15="",B15=0),0,B15*(BSD-A15+1)/(BSD-PBSD))
A16: Bonus / split retrospective factor (1 if none) | B16: 1
A17: Weighted average number of equity shares - basic | B17: =(B5+SUM(C8:C15))*B16
A19: Net profit after tax (auto from P&L, Rs) | B19: =Calc!$B$45
A20: Less: preference dividend incl tax (Setup) | B20: =Setup!C24
A21: Earnings for basic EPS | B21: =B19-B20
A22: Basic EPS (Rs) | B22: =IF(B17=0,0,B21/B17)
A24: Diluted EPS
A25: Incremental shares from dilutive potentials (options free shares, conversion shares) | B25: 0
A26: Income adjustment (interest net of tax / pref dividend saved, Rs) | B26: 0
A27: Diluted EPS (Rs) | B27: =IF(B17+B25=0,0,IF(OR(B25=0,(B21+B26)/(B17+B25)>B22),B22,(B21+B26)/(B17+B25))) | E27: Anti-dilutive potentials are ignored automatically (diluted never exceeds basic).
A29: Previous year basic EPS (Rs, as restated) | B29: 0
A30: Previous year diluted EPS (Rs) | B30: 0

Sheet Checks
B2: Checks - every row must PASS before you print
B4: Check | C4: Value | D4: Status
B5: Trial balance CY balances (Dr = Cr) | C5: =TB!B227 | D5: =IF(ROUND(ABS(C5),2)<=0.01,"PASS","CHECK")
B6: Trial balance PY balances (Dr = Cr) | C6: =TB!D227 | D6: =IF(ROUND(ABS(C6),2)<=0.01,"PASS","CHECK")
B7: All TB rows with amounts are mapped | C7: =TB!B228 | D7: =IF(ROUND(ABS(C7),2)<=0.01,"PASS","CHECK")
B8: Balance sheet balances - current year | C8: =BS!D42 | D8: =IF(ROUND(ABS(C8),2)<=0.01,"PASS","CHECK")
B9: Balance sheet balances - previous year | C9: =BS!E42 | D9: =IF(ROUND(ABS(C9),2)<=0.01,"PASS","CHECK")
B10: Borrowings grid ties to TB long-term borrowings | C10: =Borrowings!I20 | D10: =IF(ROUND(ABS(C10),2)<=0.01,"PASS","CHECK")
B11: Trade receivables ageing ties to the note total | C11: ='Notes-BS'!H171 | D11: =IF(ROUND(ABS(C11),2)<=0.01,"PASS","CHECK")
B12: Trade payables ageing ties to the note total | C12: ='Notes-BS'!G82 | D12: =IF(ROUND(ABS(C12),2)<=0.01,"PASS","CHECK")
B13: PPE (Companies Act) net block ties to TB PPE | C13: =IF('Dep-CoAct'!J12=0,0,'Dep-CoAct'!J12-Calc!$B$13) | D13: =IF(ROUND(ABS(C13),2)<=0.01,"PASS","CHECK")
B14: Share capital note ties to TB | C14: =Shareholding!C12 | D14: =IF(ROUND(ABS(C14),2)<=0.01,"PASS","CHECK")
B15: P&L profit equals profit added to reserves | C15: =PL!D24-Calc!$B$45/RND | D15: =IF(ROUND(ABS(C15),2)<=0.01,"PASS","CHECK")
B16: Share reconciliation closing equals Setup shares | C16: =Shareholding!C20 | D16: =IF(ROUND(ABS(C16),2)<=0.01,"PASS","CHECK")
B17: Cash flow reconciles to closing cash | C17: =CashFlow!C38 | D17: =IF(ROUND(ABS(C17),2)<=0.01,"PASS","CHECK")
B19: All clear? | C19: =IF(COUNTIF(D5:D17,"CHECK")=0,"ALL PASS","REVIEW ROWS MARKED CHECK")

Sheet BS
B2: Balance Sheet as at | D2: =TEXT(BSD,"dd mmmm yyyy")
B3: =Setup!C5 | D3: =Setup!C27
B4: ="CIN: "&Setup!C6&" | "&Setup!C7
B5: Particulars | C5: Note | D5: ="As at "&TEXT(BSD,"dd mmmm yyyy") | E5: ="As at "&TEXT(PBSD,"dd mmmm yyyy")
B6: I. EQUITY AND LIABILITIES
B7: 1. Shareholders funds
B8: (a) Share capital | C8: 2 | D8: =-Calc!$B$2/RND | E8: =-Calc!$C$2/RND
B9: (b) Reserves and surplus | C9: 3 | D9: =(-Calc!$B$3+Calc!$B$45)/RND | E9: =(-Calc!$C$3+Calc!$C$46)/RND
B10: 2. Non-current liabilities
B11: (a) Long-term borrowings | C11: 4 | D11: =(-Calc!$B$4-Borrowings!$J$18)/RND | E11: =(-Calc!$C$4-Borrowings!$I$27)/RND
B12: (b) Deferred tax liabilities (net) | C12: 5 | D12: =-Calc!$B$5/RND | E12: =-Calc!$C$5/RND
B13: (c) Other long-term liabilities | C13: 6 | D13: =-Calc!$B$6/RND | E13: =-Calc!$C$6/RND
B14: (d) Long-term provisions | C14: 7 | D14: =-Calc!$B$7/RND | E14: =-Calc!$C$7/RND
B15: 3. Current liabilities
B16: (a) Short-term borrowings (incl current maturities) | C16: 8 | D16: =(-Calc!$B$8+Borrowings!$J$18)/RND | E16: =(-Calc!$C$8+Borrowings!$I$27)/RND
B17: (b) Trade payables | C17: 9 | D17: =-(Calc!$B$9+Calc!$B$10)/RND | E17: =-(Calc!$C$9+Calc!$C$10)/RND
B19: (c) Other current liabilities | C19: 10 | D19: =-Calc!$B$11/RND | E19: =-Calc!$C$11/RND
B20: (d) Short-term provisions | C20: 11 | D20: =-Calc!$B$12/RND | E20: =-Calc!$C$12/RND
B21: TOTAL | D21: =SUM(D8:D20) | E21: =SUM(E8:E20)
B23: II. ASSETS
B24: 1. Non-current assets
B25: (a) Property, plant and equipment | C25: 12
B26: (i) Tangible assets | D26: =Calc!$B$13/RND | E26: =Calc!$C$13/RND
B27: (ii) Intangible assets | D27: =Calc!$B$14/RND | E27: =Calc!$C$14/RND
B28: (b) Non-current investments | C28: 13 | D28: =Calc!$B$17/RND | E28: =Calc!$C$17/RND
B29: (c) Deferred tax assets (net) | C29: 5 | D29: =Calc!$B$18/RND | E29: =Calc!$C$18/RND
B30: (d) Long-term loans and advances | C30: 14 | D30: =Calc!$B$19/RND | E30: =Calc!$C$19/RND
B31: (e) Other non-current assets | C31: 15 | D31: =Calc!$B$20/RND | E31: =Calc!$C$20/RND
B33: 2. Current assets
B34: (a) Current investments | C34: 16 | D34: =Calc!$B$21/RND | E34: =Calc!$C$21/RND
B35: (b) Inventories | C35: 17 | D35: =Calc!$B$22/RND | E35: =Calc!$C$22/RND
B36: (c) Trade receivables | C36: 18 | D36: =Calc!$B$23/RND | E36: =Calc!$C$23/RND
B37: (d) Cash and cash equivalents | C37: 19 | D37: =Calc!$B$24/RND | E37: =Calc!$C$24/RND
B38: (e) Short-term loans and advances | C38: 20 | D38: =Calc!$B$25/RND | E38: =Calc!$C$25/RND
B39: (f) Other current assets | C39: 21 | D39: =Calc!$B$26/RND | E39: =Calc!$C$26/RND
B40: TOTAL | D40: =SUM(D25:D39) | E40: =SUM(E25:E39)
B42: Check: assets minus equity and liabilities (must be zero) | D42: =D40-D21 | E42: =E40-E21
B44: Significant accounting policies (Note 1) and the accompanying notes form an integral part of the financial statements.
B46: ="Certified as per books of account"
B47: ="For "&Setup!C30 | D47: ="For and on behalf of the board of directors of"
...

Sheet PL
B2: Statement of Profit and Loss for the year ended | D2: =TEXT(BSD,"dd mmmm yyyy")
B3: =Setup!C5 | D3: =Setup!C27
B4: ="CIN: "&Setup!C6&" | "&Setup!C7
B5: Particulars | C5: Note | D5: ="Year ended "&TEXT(BSD,"dd mmmm yyyy") | E5: ="Year ended "&TEXT(PBSD,"dd mmmm yyyy")
B6: I. Revenue from operations | C6: 22 | D6: =-Calc!$B$27/RND | E6: =-Calc!$C$27/RND
B7: II. Other income | C7: 23 | D7: =-Calc!$B$28/RND | E7: =-Calc!$C$28/RND
B8: III. Total income (I + II) | D8: =D6+D7 | E8: =E6+E7
B9: IV. Expenses
B10: Cost of materials consumed | C10: 24 | D10: =Calc!$B$29/RND | E10: =Calc!$C$29/RND
B11: Purchases of stock-in-trade | D11: =Calc!$B$30/RND | E11: =Calc!$C$30/RND
B12: Changes in inventories of finished goods, WIP and stock-in-trade | D12: =Calc!$B$31/RND | E12: =Calc!$C$31/RND
B13: Employee benefits expense | C13: 25 | D13: =Calc!$B$32/RND | E13: =Calc!$C$32/RND
B14: Finance costs | C14: 26 | D14: =Calc!$B$33/RND | E14: =Calc!$C$33/RND
B15: Depreciation and amortisation expense | C15: 12 | D15: =Calc!$B$34/RND | E15: =Calc!$C$34/RND
B16: Other expenses | C16: 27 | D16: =Calc!$B$35/RND | E16: =Calc!$C$35/RND
B17: Total expenses | D17: =SUM(D10:D16) | E17: =SUM(E10:E16)
B18: V. Profit before exceptional items and tax (III - IV) | D18: =D8-D17 | E18: =E8-E17
B19: VI. Exceptional items | D19: =Calc!$B$36/RND | E19: =Calc!$C$36/RND
B20: VII. Profit before tax (V - VI) | D20: =D18-D19 | E20: =E18-E19
B21: VIII. Tax expense
B22: (1) Current tax | D22: =Calc!$B$37/RND | E22: =Calc!$C$37/RND
B23: (2) Deferred tax | C23: 5 | D23: =Calc!$B$38/RND | E23: =Calc!$C$38/RND
B24: IX. Profit for the year (VII - VIII) | D24: =D20-D22-D23 | E24: =E20-E22-E23
B26: X. Earnings per equity share (Rs): (1) Basic | C26: 28 | D26: =EPS!$B$22 | E26: =EPS!$B$29
B27: (2) Diluted | D27: =IF(Setup!C16="Yes","Exempt - SMC",EPS!$B$27) | E27: =IF(Setup!C16="Yes","Exempt - SMC",EPS!$B$30)
B29: Check: profit here vs profit added to reserves | D29: =D24-Calc!$B$45/RND
B31: Significant accounting policies (Note 1) and the accompanying notes form an integral part of the financial statements.
B33: ="Certified as per books of account"
B34: ="For "&Setup!C30 | D34: ="For and on behalf of the board of directors of"
B35: ="Chartered Accountants" | D35: =Setup!C5
B36: ="Firm Registration No. "&Setup!C31
B39: =Setup!C32 | D39: =Setup!C35 | E39: =Setup!C37
B40: =Setup!C41 | D40: =Setup!C42 | E40: =Setup!C43
B41: ="Membership No. "&Setup!C33 | D41: ="DIN: "&Setup!C36 | E41: ="DIN: "&Setup!C38
B42: ="UDIN: "&Setup!C34
B43: ="Place: "&Setup!C39
B44: ="Date: "&Setup!C40

Sheet CashFlow
B2: ="Cash Flow Statement for the year ended "&TEXT(BSD,"dd mmmm yyyy")&" (AS 3, indirect method) - in rounding units"
B3: =IF(Setup!C17="Yes","Required for this company.","Setup says a cash flow statement is NOT required (OPC/small/dormant) - hide or delete this sheet before printing.")
B5: A. Operating activities
B6: Profit before tax | C6: =PL!D20
B7: Add: depreciation and amortisation | C7: =Calc!$B$34/RND
B8: Add: finance costs | C8: =Calc!$B$33/RND
B9: Less: interest / investment income (enter) | C9: 0
B10: Operating profit before working capital changes | C10: =SUM(C6:C8)-C9
B11: (Increase)/decrease in inventories | C11: =(Calc!$C$22-Calc!$B$22)/RND
B12: (Increase)/decrease in trade receivables | C12: =(Calc!$C$23-Calc!$B$23)/RND
B13: (Increase)/decrease in loans, advances and other assets | C13: =(Calc!$C$25+Calc!$C$26+Calc!$C$19+Calc!$C$20-Calc!$B$25-Calc!$B$26-Calc!$B$19-Calc!$B$20)/RND
B14: Increase/(decrease) in trade payables | C14: =((-Calc!$B$9-Calc!$B$10)-(-Calc!$C$9-Calc!$C$10))/RND
B15: Increase/(decrease) in other liabilities and provisions | C15: =((-Calc!$B$11-Calc!$B$12-Calc!$B$6-Calc!$B$7)-(-Calc!$C$11-Calc!$C$12-Calc!$C$6-Calc!$C$7))/RND
B16: Cash generated from operations | C16: =SUM(C10:C15)
B17: Less: income taxes paid (enter) | C17: 0
B18: Net cash from operating activities (A) | C18: =C16-C17
B20: B. Investing activities
B21: Purchase of PPE/intangibles/CWIP (enter as negative) | C21: 0
B22: Proceeds from sale of PPE (enter) | C22: 0
B23: (Purchase)/sale of investments - net | C23: =(Calc!$C$17+Calc!$C$21-Calc!$B$17-Calc!$B$21)/RND
B24: Interest / investment income received (enter) | C24: 0
B25: Net cash used in investing activities (B) | C25: =SUM(C21:C24)
B27: C. Financing activities
B28: Proceeds from issue of shares | C28: =((-Calc!$B$2)-(-Calc!$C$2))/RND
B29: Borrowings raised/(repaid) - net | C29: =((-Calc!$B$4-Calc!$B$8)-(-Calc!$C$4-Calc!$C$8))/RND
B30: Finance costs paid | C30: =-Calc!$B$33/RND
B31: Dividends paid (from Note 3 input) | C31: =-'Notes-BS'!C9
B32: Net cash from financing activities (C) | C32: =SUM(C28:C31)
B34: Net increase/(decrease) in cash (A+B+C) | C34: =C18+C25+C32
B35: Cash and equivalents - opening | C35: =Calc!$C$24/RND
B36: Cash and equivalents - closing (derived) | C36: =C34+C35
B37: Closing cash per balance sheet | C37: =Calc!$B$24/RND
B38: Difference (0 when investing/financing inputs are complete) | C38: =C36-C37
B40: Significant accounting policies (Note 1) and the accompanying notes form an integral part of the financial statements.
B42: ="Certified as per books of account"
B43: ="For "&Setup!C30 | C43: ="For and on behalf of the board of directors of"
B44: ="Chartered Accountants" | C44: =Setup!C5
B45: ="Firm Registration No. "&Setup!C31
B48: =Setup!C32 | C48: =Setup!C35 | D48: =Setup!C37
B49: =Setup!C41 | C49: =Setup!C42 | D49: =Setup!C43
...

Sheet Policies
B2: Note 1 - Significant Accounting Policies (editable text)
B3: Edit freely, or generate an entity-perfect set with the free CalcGuru Accounting Policies Builder (calcguru.in/accounting-policies-generator/) and paste each paragraph over these rows.
B5: 1.1 Basis of preparation: These financial statements are prepared on the accrual basis under the historical cost convention, in accordance with the Accounting Standards notified under the Companies (Accounting Standards) Rules, 2021, the Companies Act, 2013 and Schedule III (Division I).
B7: 1.2 Use of estimates: The preparation of financial statements requires the management to make estimates and assumptions that affect the reported amounts; actual results could differ, and revisions are recognised prospectively.
B9: 1.3 Property, plant and equipment and depreciation: PPE are stated at cost less accumulated depreciation and impairment. Depreciation is provided on the written down value method over the useful lives prescribed in Schedule II to the Companies Act, 2013.
B11: 1.4 Inventories: Valued at the lower of cost (FIFO) and net realisable value; finished goods and WIP include an appropriate share of production overheads.
B13: 1.5 Revenue recognition: Revenue from sale of goods is recognised when significant risks and rewards pass to the buyer, net of returns, discounts and GST; service revenue by stage of completion; interest on a time-proportion basis.
B15: 1.6 Employee benefits: Short-term benefits are expensed as the service is rendered; contributions to defined contribution schemes are charged as incurred; gratuity is provided as per company policy.
B17: 1.7 Borrowing costs: Costs attributable to qualifying assets are capitalised to the date of readiness; all other borrowing costs are expensed.
B19: 1.8 Taxes on income: Current tax per the income-tax law in force; deferred tax on timing differences at enacted or substantively enacted rates; deferred tax assets recognised only where realisation is reasonably or virtually certain.
B21: 1.9 Provisions and contingencies: Provisions are recognised for present obligations with probable outflow and reliable estimates; contingent liabilities are disclosed and not provided; contingent assets are not recognised.
B23: 1.10 Earnings per share: Basic EPS uses the weighted average number of equity shares; diluted EPS additionally adjusts for dilutive potential equity shares.
B25: (Add or delete policies to match the entity - impairment, foreign currency, investments, MSME dues, cash flow method.)

Sheet Shareholding
B2: Note 2 - Share capital and shareholding
B3: =Setup!C5
B4: Share counts and percentages compute from the Setup share numbers; fill names and share counts in yellow. Amounts in rupees.
